<?xml version="1.0" encoding="utf-8"?>
<!-- This URDF was automatically created by SolidWorks to URDF Exporter! Originally created by Stephen Brawner (brawner@gmail.com) 
     Commit Version: 1.6.0-1-g15f4949  Build Version: 1.6.7594.29634
     For more information, please see http://wiki.ros.org/sw_urdf_exporter -->
<robot
  name="wheel_robot">
  <link
    name="body">
    <inertial>
      <origin
        xyz="-0.00345845448617114 -1.27437082478017E-07 0.0114321781136311"
        rpy="0 0 0" />
      <mass
        value="0.0900071946882429" />
      <inertia
        ixx="4.90631252188324E-05"
        ixy="-3.71280927305604E-10"
        ixz="-3.1186541655006E-06"
        iyy="9.92493244541926E-05"
        iyz="-5.34357625298288E-10"
        izz="0.000130457547159725" />
    </inertial>
    <visual>
      <origin
        xyz="0 0 0"
        rpy="0 0 0" />
      <geometry>
        <mesh
          filename="package://wheel_robot/meshes/body.STL" />
      </geometry>
      <material
        name="">
        <color
          rgba="0.792156862745098 0.819607843137255 0.933333333333333 1" />
      </material>
    </visual>
    <collision>
      <origin
        xyz="0 0 0"
        rpy="0 0 0" />
      <geometry>
        <mesh
          filename="package://wheel_robot/meshes/body.STL" />
      </geometry>
    </collision>
  </link>
  <link
    name="wheel_L1">
    <inertial>
      <origin
        xyz="-6.9389E-18 1.7347E-18 0.030308"
        rpy="0 0 0" />
      <mass
        value="0.011427" />
      <inertia
        ixx="9.9372E-07"
        ixy="-2.647E-23"
        ixz="-1.2724E-17"
        iyy="9.9372E-07"
        iyz="-1.1513E-17"
        izz="1.076E-06" />
    </inertial>
    <visual>
      <origin
        xyz="0 0 0"
        rpy="0 0 0" />
      <geometry>
        <mesh
          filename="package://wheel_robot/meshes/wheel_L1.STL" />
      </geometry>
      <material
        name="">
        <color
          rgba="0.79216 0.81961 0.93333 1" />
      </material>
    </visual>
    <collision>
      <origin
        xyz="0 0 0"
        rpy="0 0 0" />
      <geometry>
        <mesh
          filename="package://wheel_robot/meshes/wheel_L1.STL" />
      </geometry>
    </collision>
  </link>
  <joint
    name="wheel_LJ1"
    type="continuous">
    <origin
      xyz="0.0275 -0.005 0.013"
      rpy="1.5708 -0.2212 0" />
    <parent
      link="body" />
    <child
      link="wheel_L1" />
    <axis
      xyz="0 0 1" />
  </joint>
  <link
    name="wheel_L2">
    <inertial>
      <origin
        xyz="-3.4694E-18 0 0.030308"
        rpy="0 0 0" />
      <mass
        value="0.011427" />
      <inertia
        ixx="9.9372E-07"
        ixy="-3.6957E-23"
        ixz="-1.2724E-17"
        iyy="9.9372E-07"
        iyz="-1.1513E-17"
        izz="1.076E-06" />
    </inertial>
    <visual>
      <origin
        xyz="0 0 0"
        rpy="0 0 0" />
      <geometry>
        <mesh
          filename="package://wheel_robot/meshes/wheel_L2.STL" />
      </geometry>
      <material
        name="">
        <color
          rgba="0.79216 0.81961 0.93333 1" />
      </material>
    </visual>
    <collision>
      <origin
        xyz="0 0 0"
        rpy="0 0 0" />
      <geometry>
        <mesh
          filename="package://wheel_robot/meshes/wheel_L2.STL" />
      </geometry>
    </collision>
  </link>
  <joint
    name="wheel_LJ2"
    type="continuous">
    <origin
      xyz="-0.0275 -0.005 0.013"
      rpy="1.5708 0 0" />
    <parent
      link="body" />
    <child
      link="wheel_L2" />
    <axis
      xyz="0 0 1" />
  </joint>
  <link
    name="wheel_R1">
    <inertial>
      <origin
        xyz="-2.46330733588707E-16 6.93889390390723E-18 -0.030308288856835"
        rpy="0 0 0" />
      <mass
        value="0.0114267079612173" />
      <inertia
        ixx="9.93716942507501E-07"
        ixy="-5.70945968762743E-23"
        ixz="-1.27233219610879E-17"
        iyy="9.93716942507501E-07"
        iyz="1.15124972222447E-17"
        izz="1.0759637694368E-06" />
    </inertial>
    <visual>
      <origin
        xyz="0 0 0"
        rpy="0 0 0" />
      <geometry>
        <mesh
          filename="package://wheel_robot/meshes/wheel_R1.STL" />
      </geometry>
      <material
        name="">
        <color
          rgba="0.792156862745098 0.819607843137255 0.933333333333333 1" />
      </material>
    </visual>
    <collision>
      <origin
        xyz="0 0 0"
        rpy="0 0 0" />
      <geometry>
        <mesh
          filename="package://wheel_robot/meshes/wheel_R1.STL" />
      </geometry>
    </collision>
  </link>
  <joint
    name="wheel_RJ1"
    type="continuous">
    <origin
      xyz="0.0275 0.005 0.013"
      rpy="1.5708 0 0" />
    <parent
      link="body" />
    <child
      link="wheel_R1" />
    <axis
      xyz="0 0 -1" />
  </joint>
  <link
    name="wheel_R2">
    <inertial>
      <origin
        xyz="3.46944695195361E-18 -3.46944695195361E-18 -0.0303082888568349"
        rpy="0 0 0" />
      <mass
        value="0.0114267079612173" />
      <inertia
        ixx="9.93716942507502E-07"
        ixy="-2.24993126614424E-22"
        ixz="-1.27240957786686E-17"
        iyy="9.93716942507502E-07"
        iyz="1.15126860823422E-17"
        izz="1.07596376943681E-06" />
    </inertial>
    <visual>
      <origin
        xyz="0 0 0"
        rpy="0 0 0" />
      <geometry>
        <mesh
          filename="package://wheel_robot/meshes/wheel_R2.STL" />
      </geometry>
      <material
        name="">
        <color
          rgba="0.792156862745098 0.819607843137255 0.933333333333333 1" />
      </material>
    </visual>
    <collision>
      <origin
        xyz="0 0 0"
        rpy="0 0 0" />
      <geometry>
        <mesh
          filename="package://wheel_robot/meshes/wheel_R2.STL" />
      </geometry>
    </collision>
  </link>
  <joint
    name="wheel_RJ2"
    type="continuous">
    <origin
      xyz="-0.0275 0.005 0.013"
      rpy="1.5708 -0.22488 0" />
    <parent
      link="body" />
    <child
      link="wheel_R2" />
    <axis
      xyz="0 0 -1" />
  </joint>
  <link
    name="lidar">
    <inertial>
      <origin
        xyz="-3.46944695195361E-18 -1.89580779882133E-19 0.00382014388489209"
        rpy="0 0 0" />
      <mass
        value="0.000655022068273471" />
      <inertia
        ixx="8.77065641646922E-09"
        ixy="-1.34506811361043E-41"
        ixz="-1.82374187768398E-41"
        iyy="8.77065641646922E-09"
        iyz="4.5783991086801E-25"
        izz="1.5208646385569E-08" />
    </inertial>
    <visual>
      <origin
        xyz="0 0 0"
        rpy="0 0 0" />
      <geometry>
        <mesh
          filename="package://wheel_robot/meshes/lidar.STL" />
      </geometry>
      <material
        name="">
        <color
          rgba="0.792156862745098 0.819607843137255 0.933333333333333 1" />
      </material>
    </visual>
    <collision>
      <origin
        xyz="0 0 0"
        rpy="0 0 0" />
      <geometry>
        <mesh
          filename="package://wheel_robot/meshes/lidar.STL" />
      </geometry>
    </collision>
  </link>
  <joint
    name="lidar_joint"
    type="fixed">
    <origin
      xyz="-0.0275 0 0.028"
      rpy="0 0 0" />
    <parent
      link="body" />
    <child
      link="lidar" />
    <axis
      xyz="0 0 0" />
  </joint>
  <link
    name="camera">
    <inertial>
      <origin
        xyz="-0.00286548223350253 -9.95404832614943E-18 2.77555756156289E-17"
        rpy="0 0 0" />
      <mass
        value="0.000154723438189297" />
      <inertia
        ixx="8.29871334399828E-10"
        ixy="4.81866151369425E-25"
        ixz="-1.40289814515442E-24"
        iyy="6.97759074109873E-10"
        iyz="-6.68959257195479E-39"
        izz="6.97759074109873E-10" />
    </inertial>
    <visual>
      <origin
        xyz="0 0 0"
        rpy="0 0 0" />
      <geometry>
        <mesh
          filename="package://wheel_robot/meshes/camera.STL" />
      </geometry>
      <material
        name="">
        <color
          rgba="0.792156862745098 0.819607843137255 0.933333333333333 1" />
      </material>
    </visual>
    <collision>
      <origin
        xyz="0 0 0"
        rpy="0 0 0" />
      <geometry>
        <mesh
          filename="package://wheel_robot/meshes/camera.STL" />
      </geometry>
    </collision>
  </link>
  <joint
    name="camera_joint"
    type="fixed">
    <origin
      xyz="-0.0305 0 0.025"
      rpy="0 0 0" />
    <parent
      link="body" />
    <child
      link="camera" />
    <axis
      xyz="0 0 0" />
  </joint>
</robot>